<?xml version="1.0" ?>
<robot name="myArm">
    <!-- Base link -->
    <link name="base_link">
        <visual>
            <geometry>
                <box size="4 4 1" />
            </geometry>
        </visual>
        <collision>
            <geometry>
                <box size="4 4 1" />
            </geometry>
        </collision>
        <inertial>
            <mass value="0.1" />
            <origin xyz="0 0 0" rpy="0 0 0" />
            <inertia ixx="0.03" iyy="0.03" izz="0.03" ixy="0.0" ixz="0.0" iyz="0.0" />
        </inertial>
    </link>
    <!-- Links and Artificial Ball Joints -->
    <link name="arm1">
        <visual>
            <geometry>
                <cylinder length="3" radius="0.5" />
            </geometry>
            <origin rpy="0 0 0" xyz="0 0 1.5" />
        </visual>
        <collision>
            <geometry>
                <cylinder length="3" radius="0.5" />
            </geometry>
            <origin rpy="0 0 0" xyz="0 0 1.5" />
        </collision>
        <inertial>
            <mass value="0.1" />
            <origin xyz="0 0 0" rpy="0 0 0" />
            <inertia ixx="0.03" iyy="0.03" izz="0.03" ixy="0.0" ixz="0.0" iyz="0.0" />
        </inertial>
    </link>
    <link name="sphere1">
        <visual>
            <geometry>
                <sphere radius="0.75" />
            </geometry>
            <origin rpy="0 0 0" xyz="0 0 0" />
        </visual>
        <collision>
            <geometry>
                <sphere radius="0.75" />
            </geometry>
            <origin rpy="0 0 0" xyz="0 0 0" />
        </collision>
        <inertial>
            <mass value="0.1" />
            <origin xyz="0 0 0" rpy="0 0 0" />
            <inertia ixx="0.03" iyy="0.03" izz="0.03" ixy="0.0" ixz="0.0" iyz="0.0" />
        </inertial>
    </link>
    <link name="arm2">
        <visual>
            <geometry>
                <cylinder length="3" radius="0.5" />
            </geometry>
            <origin rpy="0 0 0" xyz="0 0 2.25" />
        </visual>
        <collision>
            <geometry>
                <cylinder length="3" radius="0.5" />
            </geometry>
            <origin rpy="0 0 0" xyz="0 0 2.25" />
        </collision>
        <inertial>
            <mass value="0.1" />
            <origin xyz="0 0 0" rpy="0 0 0" />
            <inertia ixx="0.03" iyy="0.03" izz="0.03" ixy="0.0" ixz="0.0" iyz="0.0" />
        </inertial>
    </link>
    <link name="sphere2">
        <visual>
            <geometry>
                <sphere radius="0.75" />
            </geometry>
            <origin rpy="0 0 0" xyz="0 0 0" />
        </visual>
        <collision>
            <geometry>
                <sphere radius="0.75" />
            </geometry>
            <origin rpy="0 0 0" xyz="0 0 0" />
        </collision>
        <inertial>
            <mass value="0.1" />
            <origin xyz="0 0 0" rpy="0 0 0" />
            <inertia ixx="0.03" iyy="0.03" izz="0.03" ixy="0.0" ixz="0.0" iyz="0.0" />
        </inertial>
    </link>
    <link name="arm3">
        <visual>
            <geometry>
                <cylinder length="3" radius="0.5" />
            </geometry>
            <origin rpy="0 0 0" xyz="0 0 2.25" />
        </visual>
        <collision>
            <geometry>
                <cylinder length="3" radius="0.5" />
            </geometry>
            <origin rpy="0 0 0" xyz="0 0 2.25" />
        </collision>
        <inertial>
            <mass value="0.1" />
            <origin xyz="0 0 0" rpy="0 0 0" />
            <inertia ixx="0.03" iyy="0.03" izz="0.03" ixy="0.0" ixz="0.0" iyz="0.0" />
        </inertial>
    </link>
    <!-- Prismatic End Effector -->
    <link name="prismatic_link">
        <visual>
            <geometry>
                <cylinder length="2" radius="0.1" />
            </geometry>
            <origin rpy="0 0 0" xyz="0 0 0" />
        </visual>
        <collision>
            <geometry>
                <cylinder length="2" radius="0.1" />
            </geometry>
            <origin rpy="0 0 0" xyz="0 0 0" />
        </collision>
        <inertial>
            <mass value="0.1" />
            <origin xyz="0 0 0" rpy="0 0 0" />
            <inertia ixx="0.03" iyy="0.03" izz="0.03" ixy="0.0" ixz="0.0" iyz="0.0" />
        </inertial>
    </link>
    <link name="end_effector">
        <visual>
            <geometry>
                <sphere radius="0.1" />
            </geometry>
            <origin rpy="0 0 0" xyz="0 0 0" />
        </visual>
        <collision>
            <geometry>
                <sphere radius="0.1" />
            </geometry>
            <origin rpy="0 0 0" xyz="0 0 0" />
        </collision>
        <inertial>
            <mass value="0.1" />
            <origin xyz="0 0 0" rpy="0 0 0" />
            <inertia ixx="0.03" iyy="0.03" izz="0.03" ixy="0.0" ixz="0.0" iyz="0.0" />
        </inertial>
    </link>
    <!-- Joints -->
    <joint name="base_to_arm1" type="continuous">
        <parent link="base_link" />
        <child link="arm1" />
        <origin rpy="0 0 0" xyz="0 0 0.5" />
        <axis xyz="0 0 1" />
        <limit effort="30" velocity="1.0" />
    </joint>
    <joint name="arm1_to_sphere1" type="revolute">
        <parent link="arm1" />
        <child link="sphere1" />
        <origin rpy="0 0 0" xyz="0 0 3.75" />
        <axis xyz="0 1 0" />
        <limit effort="30" velocity="1.0" lower="-1.57" upper="1.57" />
    </joint>
    <joint name="sphere1_to_arm2" type="revolute">
        <parent link="sphere1" />
        <child link="arm2" />
        <origin rpy="0 0 0" xyz="0 0 0" />
        <axis xyz="0 0 1" />
        <limit effort="30" velocity="1.0" lower="-3.14" upper="3.14" />
    </joint>
    <joint name="arm2_to_sphere2" type="revolute">
        <parent link="arm2" />
        <child link="sphere2" />
        <origin rpy="0 0 0" xyz="0 0 4.5" />
        <axis xyz="0 1 0" />
        <limit effort="30" velocity="1.0" lower="-1.57" upper="1.57" />
    </joint>
    <joint name="sphere2_to_arm3" type="revolute">
        <parent link="sphere2" />
        <child link="arm3" />
        <origin rpy="0 0 0" xyz="0 0 0" />
        <axis xyz="1 0 0" />
        <limit effort="30" velocity="1.0" lower="-1.57" upper="1.57" />
    </joint>
    <joint name="arm3_to_prismatic" type="prismatic">
        <parent link="arm3" />
        <child link="prismatic_link" />
        <origin rpy="0 0 0" xyz="0 0 3.75" />
        <axis xyz="0 0 1" />
        <limit effort="30" velocity="1.0" lower="-1" upper="1" />
    </joint>
    <!-- End Effector -->
    <joint name="prismatic_to_end_effector" type="fixed">
        <parent link="prismatic_link" />
        <child link="end_effector" />
        <origin rpy="0 0 0" xyz="0 0 1.1" />
    </joint>
    <transmission name="trans_base_to_arm1">
        <type>transmission_interface/SimpleTransmission</type>
        <joint name="base_to_arm1">
            <hardwareInterface>hardware_interface/EffortJointInterface</hardwareInterface>
        </joint>
        <actuator name="base_to_arm1_motor">
            <hardwareInterface>hardware_interface/EffortJointInterface</hardwareInterface>
            <mechanicalReduction>1</mechanicalReduction>
        </actuator>
    </transmission>
    <transmission name="trans_arm1_to_sphere1">
        <type>transmission_interface/SimpleTransmission</type>
        <joint name="arm1_to_sphere1">
            <hardwareInterface>hardware_interface/EffortJointInterface</hardwareInterface>
        </joint>
        <actuator name="arm1_to_sphere1_motor">
            <hardwareInterface>hardware_interface/EffortJointInterface</hardwareInterface>
            <mechanicalReduction>1</mechanicalReduction>
        </actuator>
    </transmission>
    <transmission name="trans_sphere1_to_arm2">
        <type>transmission_interface/SimpleTransmission</type>
        <joint name="sphere1_to_arm2">
            <hardwareInterface>hardware_interface/EffortJointInterface</hardwareInterface>
        </joint>
        <actuator name="sphere1_to_arm2_motor">
            <hardwareInterface>hardware_interface/EffortJointInterface</hardwareInterface>
            <mechanicalReduction>1</mechanicalReduction>
        </actuator>
    </transmission>
    <transmission name="trans_arm2_to_sphere2">
        <type>transmission_interface/SimpleTransmission</type>
        <joint name="arm2_to_sphere2">
            <hardwareInterface>hardware_interface/EffortJointInterface</hardwareInterface>
        </joint>
        <actuator name="arm2_to_sphere2_motor">
            <hardwareInterface>hardware_interface/EffortJointInterface</hardwareInterface>
            <mechanicalReduction>1</mechanicalReduction>
        </actuator>
    </transmission>
    <transmission name="trans_sphere2_to_arm3">
        <type>transmission_interface/SimpleTransmission</type>
        <joint name="sphere2_to_arm3">
            <hardwareInterface>hardware_interface/EffortJointInterface</hardwareInterface>
        </joint>
        <actuator name="sphere2_to_arm3_motor">
            <hardwareInterface>hardware_interface/EffortJointInterface</hardwareInterface>
            <mechanicalReduction>1</mechanicalReduction>
        </actuator>
    </transmission>
    <transmission name="trans_arm3_to_prismatic">
        <type>transmission_interface/SimpleTransmission</type>
        <joint name="arm3_to_prismatic">
            <hardwareInterface>hardware_interface/EffortJointInterface</hardwareInterface>
        </joint>
        <actuator name="arm3_to_prismatic_motor">
            <hardwareInterface>hardware_interface/EffortJointInterface</hardwareInterface>
            <mechanicalReduction>1</mechanicalReduction>
        </actuator>
    </transmission>
    <gazebo>
        <plugin name="gazebo_ros_control">
            <robotNamespace>/</robotNamespace>
        </plugin>
    </gazebo>
</robot>

